Workbook

Sheet 00_Inicio
A1: AG LEGAL | Sistema financiero y comercial 2026
A2: Modelo reconstruido a partir del detalle mensual. Separa cobrado, cartera en ejecución y presupuesto julio-diciembre.
A4: Regla | B4: Aplicación
A5: Código | B5: AGL-Categoría-Subcategoría-000
A6: Clasificación | B6: Cada servicio tiene una categoría financiera principal y múltiples etiquetas.
A7: Duplicados | B7: No se duplica el mismo servicio; se relaciona mediante etiquetas y servicios vinculados.
A8: Ingreso | B8: Solo dinero efectivamente cobrado.
A9: Cartera | B9: Trabajo contratado o ganado que requiere finalizarse antes del cobro.
A10: Proyección | B10: Cobro esperado por mes, ajustado por probabilidad.
A11: Corrección David Juárez | B11: Honorarios $1,500; adelanto cobrado $200; saldo pendiente $1,300.
A14: Hoja | B14: Uso principal | C14: Usuario | D14: Carácter
A15: 12_Reglas_Comision | B15: Reglas de salario variable de Andrea | C15: Administración / desarrollador | D15: Normativo
A16: 13_Especificacion_Sistema | B16: Modelo de datos y reglas de implementación | C16: Desarrollador | D16: Crítico
A17: 14_Dashboard_KPIs | B17: Indicadores y visuales requeridos | C17: Desarrollador / socios | D17: Crítico
A18: 15_Cumplimiento_Metas | B18: Estructura de seguimiento meta vs real | C18: Sistema / administración | D18: Operativo
A19: 03_Catalogo_Servicios | B19: Maestro de códigos a importar | C19: Desarrollador | D19: Crítico
A21: Hoja | B21: Contenido | C21: Uso | D21: Importancia
A22: 04_Plan_Cuentas | B22: Códigos oficiales de ingresos y egresos | C22: Importar al sistema | D22: Crítica
A23: 15_Cumplimiento_Metas | B23: Meta y realidad por familia/mes | C23: Control temporal y sistema | D23: Crítica
A24: 16_Movimientos_Codificados | B24: Estructura de cada movimiento financiero | C24: Desarrollo e importación | D24: Crítica
A25: 17_Resumen_Mensual | B25: Meta, utilidad mínima y cumplimiento consolidado | C25: Dashboard y socios | D25: Crítica
A27: Hoja | B27: Contenido | C27: Responsable principal | D27: Uso
... A34: PEN | B34: Derecho Penal creado como categoría independiente | C34: Catálogo y sistema | D34: Crítica
A36: HOJA PRINCIPAL PARA ENVIAR AL DESARROLLADOR
A37: Hoja | B37: Qué contiene | C37: Acción | D37: Prioridad
A38: 00_PARA_DESARROLLADOR | B38: Resumen único de arquitectura, campos, relaciones, dashboard y fuentes maestras | C38: Leer primero | D38: Crítica
A39: 13_Especificacion_Sistema | B39: Anexo técnico ampliado | C39: Consultar después | D39: Alta

Sheet 01_Categorias
A1: 01 | Categorías maestras
A2: Las categorías representan líneas jurídicas o comerciales independientes. Los códigos son permanentes y no reutilizables.
A4: Código | B4: Categoría | C4: Descripción | D4: Estado
A5: NOT | B5: Servicios Notariales | C5: Actos y diligencias formalizados mediante función notarial. | D5: Activo
A6: LIT | B6: Litigios y Controversias | C6: Representación judicial y solución de controversias. | D6: Activo
A7: PEN | B7: Derecho Penal | C7: Defensa penal, representación de víctimas, actuación ante FGR y tribunales, delitos económicos y ejecución penal. | D7: Activo
A8: FAM | B8: Derecho de Familia | C8: Procesos familiares, filiación, alimentos y autoridad parental. | D8: Activo
A9: COR | B9: Corporativo y Empresarial | C9: Sociedades, gobierno corporativo y asesoría empresarial. | D9: Activo
A10: RAI | B10: Bienes Raíces e Inversiones | C10: Operaciones inmobiliarias, registrales, catastrales y de inversión. | D10: Activo
A11: ADM | B11: Derecho Administrativo | C11: Procedimientos y trámites ante instituciones públicas. | D11: Activo
A12: MIG | B12: Migración y Extranjería | C12: Residencias, naturalización, NIT y regularización migratoria. | D12: Activo
A13: REL | B13: Relocalización | C13: Acompañamiento integral para establecerse o invertir en El Salvador. | D13: Activo
A14: LAB | B14: Laboral Preventivo | C14: Contratos, reglamentos, terminaciones e inspecciones laborales. | D14: Activo
A15: IPI | B15: Propiedad Intelectual | C15: Marcas, derechos de autor, patentes y diseños. | D15: Activo
... A20: CTR | B20: Contratos y Obligaciones | C20: Redacción, revisión y negociación contractual. | D20: Activo

Sheet 02_Subcategorias
A1: 02 | Subcategorías maestras
A2: Cada subcategoría pertenece a una categoría activa y utiliza un código único de tres letras distinto del código de su categoría.
A4: Código categoría | B4: Categoría | C4: Código subcategoría | D4: Subcategoría | E4: Código compuesto | F4: Estado
A5: NOT | B5: Servicios Notariales | C5: EST | D5: Escrituras sobre inmuebles | E5: NOT-EST | F5: Activo
A6: NOT | B6: Servicios Notariales | C6: VEH | D6: Instrumentos sobre vehículos | E6: NOT-VEH | F6: Activo
A7: NOT | B7: Servicios Notariales | C7: EFA | D7: Estado familiar | E7: NOT-EFA | F7: Activo
A8: NOT | B8: Servicios Notariales | C8: PAT | D8: Patrimonial notarial | E8: NOT-PAT | F8: Activo
A9: NOT | B9: Servicios Notariales | C9: OBL | D9: Obligaciones notariales | E9: NOT-OBL | F9: Activo
A10: NOT | B10: Servicios Notariales | C10: POD | D10: Poderes | E10: NOT-POD | F10: Activo
A11: NOT | B11: Servicios Notariales | C11: AUC | D11: Auténticas y certificaciones | E11: NOT-AUC | F11: Activo
A12: NOT | B12: Servicios Notariales | C12: DIL | D12: Diligencias notariales | E12: NOT-DIL | F12: Activo
A13: LIT | B13: Litigios y Controversias | C13: MER | D13: Mercantil | E13: LIT-MER | F13: Activo
A14: LIT | B14: Litigios y Controversias | C14: CIV | D14: Civil | E14: LIT-CIV | F14: Activo
A15: LIT | B15: Litigios y Controversias | C15: TRL | D15: Laboral contencioso | E15: LIT-TRL | F15: Activo
... A83: PEN | B83: Derecho Penal | C83: PJV | D83: Justicia penal juvenil | E83: PEN-PJV | F83: Activo

Sheet 03_Catalogo_Servicios
A1: 03 | Catálogo maestro de servicios
A2: Derecho Penal se administra como categoría independiente. Los códigos existentes de otras áreas se conservan para proteger el histórico.
A4: Código servicio | B4: Cod. categoría | C4: Categoría | D4: Cod. subcategoría | E4: Subcategoría | F4: Servicio | G4: Etiquetas | H4: Estado | I4: Unidad de cobro | J4: Responsable | K4: Tarifa referencia ($) | L4: Costo directo referencia ($) | M4: Horas estándar | N4: Margen referencia ($)
A5: AGL-NOT-EST-001 | B5: NOT | C5: Servicios Notariales | D5: EST | E5: Escrituras sobre inmuebles | F5: Escritura de compraventa de inmueble | G5: escritura,inmueble,CNR | H5: Activo | I5: Por definir | J5: Por definir | K5: 0 | L5: 0 | M5: 0 | N5: =K5-L5 -> 0
A6: AGL-NOT-EST-002 | B6: NOT | C6: Servicios Notariales | D6: EST | E6: Escrituras sobre inmuebles | F6: Promesa de compraventa de inmueble | G6: escritura,inmueble,CNR | H6: Activo | I6: Por definir | J6: Por definir | K6: 0 | L6: 0 | M6: 0 | N6: =K6-L6 -> 0
A7: AGL-NOT-EST-003 | B7: NOT | C7: Servicios Notariales | D7: EST | E7: Escrituras sobre inmuebles | F7: Escritura de donación de inmueble | G7: escritura,inmueble,CNR | H7: Activo | I7: Por definir | J7: Por definir | K7: 0 | L7: 0 | M7: 0 | N7: =K7-L7 -> 0
A8: AGL-NOT-EST-004 | B8: NOT | C8: Servicios Notariales | D8: EST | E8: Escrituras sobre inmuebles | F8: Cancelación notarial de hipoteca | G8: escritura,inmueble,CNR | H8: Activo | I8: Por definir | J8: Por definir | K8: 0 | L8: 0 | M8: 0 | N8: =K8-L8 -> 0
A9: AGL-NOT-VEH-001 | B9: NOT | C9: Servicios Notariales | D9: VEH | E9: Instrumentos sobre vehículos | F9: Compraventa de vehículo | G9: vehículo,tránsito | H9: Activo | I9: Por definir | J9: Por definir | K9: 0 | L9: 0 | M9: 0 | N9: =K9-L9 -> 0
A10: AGL-NOT-VEH-002 | B10: NOT | C10: Servicios Notariales | D10: VEH | E10: Instrumentos sobre vehículos | F10: Arrendamiento de vehículo | G10: vehículo,tránsito | H10: Activo | I10: Por definir | J10: Por definir | K10: 0 | L10: 0 | M10: 0 | N10: =K10-L10 -> 0
A11: AGL-NOT-VEH-003 | B11: NOT | C11: Servicios Notariales | D11: VEH | E11: Instrumentos sobre vehículos | F11: Autorización de salida de vehículo | G11: vehículo,tránsito | H11: Activo | I11: Por definir | J11: Por definir | K11: 0 | L11: 0 | M11: 0 | N11: =K11-L11 -> 0
A12: AGL-NOT-EFA-001 | B12: NOT | C12: Servicios Notariales | D12: EFA | E12: Estado familiar | F12: Matrimonio civil | G12: familia,matrimonio,menor | H12: Activo | I12: Por definir | J12: Por definir | K12: 0 | L12: 0 | M12: 0 | N12: =K12-L12 -> 0
A13: AGL-NOT-EFA-002 | B13: NOT | C13: Servicios Notariales | D13: EFA | E13: Estado familiar | F13: Reconocimiento voluntario de hijo | G13: familia,matrimonio,menor | H13: Activo | I13: Por definir | J13: Por definir | K13: 0 | L13: 0 | M13: 0 | N13: =K13-L13 -> 0
A14: AGL-NOT-EFA-003 | B14: NOT | C14: Servicios Notariales | D14: EFA | E14: Estado familiar | F14: Permiso de salida de menor | G14: familia,matrimonio,menor | H14: Activo | I14: Por definir | J14: Por definir | K14: 0 | L14: 0 | M14: 0 | N14: =K14-L14 -> 0
A15: AGL-NOT-EFA-004 | B15: NOT | C15: Servicios Notariales | D15: EFA | E15: Estado familiar | F15: Autorización para pasaporte de menor | G15: familia,matrimonio,menor | H15: Activo | I15: Por definir | J15: Por definir | K15: 0 | L15: 0 | M15: 0 | N15: =K15-L15 -> 0
A16: AGL-NOT-EFA-005 | B16: NOT | C16: Servicios Notariales | D16: EFA | E16: Estado familiar | F16: Acta notarial relacionada con familia | G16: familia,matrimonio,menor | H16: Activo | I16: Por definir | J16: Por definir | K16: 0 | L16: 0 | M16: 0 | N16: =K16-L16 -> 0
... A209: AGL-PEN-PJV-002 | B209: PEN | C209: Derecho Penal | D209: PJV | E209: Justicia penal juvenil | F209: Representación de víctima en proceso penal juvenil | G209: penal juvenil,victima | H209: Activo | I209: Por definir | J209: Por definir | K209: 0 | L209: 0 | M209: 0 | N209: =K209-L209 -> 0

Sheet 04_Registro_Operaciones
A1: 04 | Registro histórico de operaciones
A2: Registro reconstruido de marzo a julio. Ingreso significa cobrado; egreso significa pagado.
A4: Fecha | B4: Mes | C4: Cliente | D4: Concepto original | E4: Tipo | F4: Monto ($) | G4: Estado | H4: Código servicio | I4: Servicio normalizado | J4: Notas
A5: 46082 | B5: Marzo | C5: Lic. Palma | D5: Escritura de compraventa | E5: Ingreso | F5: 250 | G5: Cobrado | H5: AGL-NOT-INM-001 | I5: Escritura de compraventa de inmueble
A6: 46082 | B6: Marzo | C6: Varios | D6: Certificación de documentos | E6: Ingreso | F6: 96 | G6: Cobrado | H6: AGL-NOT-AUT-002 | I6: Certificación de documentos
A7: 46082 | B7: Marzo | C7: Emiliano | D7: Asesoría legal | E7: Ingreso | F7: 50 | G7: Cobrado | H7: AGL-ADM-REG-001 | I7: Gestión ante institución pública
A8: 46082 | B8: Marzo | C8: Andre Pranckevicius | D8: Elaboración de escrito | E8: Ingreso | F8: 50 | G8: Cobrado | H8: AGL-ADM-REG-001 | I8: Gestión ante institución pública
A9: 46092 | B9: Marzo | C9: Santos Alonso Canales | D9: Acompañamiento administrativo | E9: Ingreso | F9: 50 | G9: Cobrado | H9: AGL-ADM-REG-002 | I9: Acompañamiento administrativo
A10: 46094 | B10: Marzo | C10: Lic. Palma | D10: Alquiler de instalaciones | E10: Ingreso | F10: 80 | G10: Cobrado
A11: 46095 | B11: Marzo | C11: Douglas | D11: Alquiler de instalaciones | E11: Ingreso | F11: 10 | G11: Cobrado
A12: 46098 | B12: Marzo | C12: Patricia de Hernández | D12: Poder, asesoría y conciliación | E12: Ingreso | F12: 200 | G12: Cobrado | H12: AGL-NOT-POD-003 | I12: Poder especial
A13: 46098 | B13: Marzo | C13: Lucio Orellana | D13: Poder judicial | E13: Ingreso | F13: 50 | G13: Cobrado | H13: AGL-NOT-POD-001 | I13: Poder general judicial
A14: 46098 | B14: Marzo | C14: Yoni Estuardo | D14: Acompañamientos a Migración | E14: Ingreso | F14: 45 | G14: Cobrado | H14: AGL-MIG-PER-002 | I14: Acompañamiento a Migración
A15: 46099 | B15: Marzo | C15: PGR | D15: Acta notarial deuda alimenticia | E15: Ingreso | F15: 10 | G15: Cobrado | H15: AGL-NOT-AUT-004 | I15: Acta notarial
A16: 46100 | B16: Marzo | C16: ISSS | D16: Acta notarial | E16: Ingreso | F16: 10 | G16: Cobrado | H16: AGL-NOT-AUT-004 | I16: Acta notarial
A17: 46101 | B17: Marzo | C17: José Antonio Mineros | D17: Asesoría legal | E17: Ingreso | F17: 30 | G17: Cobrado | H17: AGL-ADM-REG-001 | I17: Gestión ante institución pública
A18: 46101 | B18: Marzo | C18: José Antonio Mineros | D18: Negociación de deuda BAC | E18: Ingreso | F18: 30 | G18: Cobrado | H18: AGL-LIT-ADR-001 | I18: Negociación extrajudicial
A19: 46102 | B19: Marzo | C19: Karla Muñoz | D19: Cesión de derechos hereditarios | E19: Ingreso | F19: 50 | G19: Cobrado | H19: AGL-NOT-PAT-003 | I19: Cesión de derechos hereditarios
A20: 46102 | B20: Marzo | C20: Karla Muñoz | D20: Aceptación de herencia | E20: Ingreso | F20: 50 | G20: Cobrado | H20: AGL-NOT-PAT-002 | I20: Aceptación de herencia notarial
A21: 46105 | B21: Marzo | C21: Ana Jovel | D21: Visita a municipalidad | E21: Ingreso | F21: 30 | G21: Cobrado | H21: AGL-ADM-MUN-001 | I21: Trámite ante Alcaldía
A22: 46105 | B22: Marzo | C22: Samuel Padillas | D22: Cancelación de hipoteca | E22: Ingreso | F22: 50 | G22: Cobrado | H22: AGL-NOT-INM-004 | I22: Cancelación notarial de hipoteca
A23: 46112 | B23: Marzo | D23: Reparaciones e insumos | E23: Egreso | F23: 16.2 | G23: Pagado | J23: Resumen reconstruido del archivo fuente
A24: 46112 | B24: Marzo | D24: Viáticos CNR | E24: Egreso | F24: 10 | G24: Pagado | J24: Resumen reconstruido del archivo fuente
A25: 46112 | B25: Marzo | D25: Servicios notariales terceros | E25: Egreso | F25: 150 | G25: Pagado | J25: Resumen reconstruido del archivo fuente
A26: 46112 | B26: Marzo | D26: Renta | E26: Egreso | F26: 400 | G26: Pagado | J26: Resumen reconstruido del archivo fuente
A27: 46112 | B27: Marzo | D27: Sueldo | E27: Egreso | F27: 250 | G27: Pagado | J27: Resumen reconstruido del archivo fuente
A28: 46118 | B28: Abril | C28: Marcela Vaquero | D28: Autorización salida de vehículo | E28: Ingreso | F28: 25 | G28: Cobrado | H28: AGL-NOT-VEH-003 | I28: Autorización de salida de vehículo
A29: 46119 | B29: Abril | C29: Varios | D29: Compraventa de vehículo | E29: Ingreso | F29: 25 | G29: Cobrado | H29: AGL-NOT-VEH-001 | I29: Compraventa de vehículo
A30: 46120 | B30: Abril | C30: David Juárez | D30: Investigación sobre herencia | E30: Ingreso | F30: 30 | G30: Cobrado | H30: AGL-INM-REG-001 | I30: Investigación registral
A31: 46127 | B31: Abril | C31: Ana María Linares | D31: Donaciones | E31: Ingreso | F31: 204 | G31: Cobrado | H31: AGL-NOT-INM-003 | I31: Escritura de donación de inmueble
A32: 46134 | B32: Abril | C32: Marvin Villalta | D32: Contratos de arrendamiento | E32: Ingreso | F32: 90 | G32: Cobrado | H32: AGL-INM-ARR-001 | I32: Contrato de arrendamiento residencial
A33: 46136 | B33: Abril | C33: Inversiones ZR | D33: Compraventa de vehículos | E33: Ingreso | F33: 50 | G33: Cobrado | H33: AGL-NOT-VEH-001 | I33: Compraventa de vehículo
A34: 46136 | B34: Abril | C34: Inversiones ZR | D34: Reimpresión compraventa vehículo | E34: Ingreso | F34: 10 | G34: Cobrado | H34: AGL-NOT-VEH-001 | I34: Compraventa de vehículo
A35: 46136 | B35: Abril | C35: Douglas | D35: Alquiler de instalaciones | E35: Ingreso | F35: 10 | G35: Cobrado
A36: 46137 | B36: Abril | C36: Margarita Vaquerano | D36: Asesoría | E36: Ingreso | F36: 30 | G36: Cobrado | H36: AGL-ADM-REG-001 | I36: Gestión ante institución pública
A37: 46142 | B37: Abril | D37: Certificaciones y tasas | E37: Egreso | F37: 26.36 | G37: Pagado | J37: Resumen reconstruido del archivo fuente
A38: 46142 | B38: Abril | D38: Capacitación | E38: Egreso | F38: 75 | G38: Pagado | J38: Resumen reconstruido del archivo fuente
A39: 46142 | B39: Abril | D39: Energía eléctrica | E39: Egreso | F39: 11.14 | G39: Pagado | J39: Resumen reconstruido del archivo fuente
A40: 46142 | B40: Abril | D40: Renta | E40: Egreso | F40: 400 | G40: Pagado | J40: Resumen reconstruido del archivo fuente
A41: 46142 | B41: Abril | D41: Sueldo | E41: Egreso | F41: 450 | G41: Pagado | J41: Resumen reconstruido del archivo fuente
...

Sheet 05_Cartera_Proyectos
A1: 05 | Cartera y proyectos en ejecución
A2: Los importes pendientes no se consideran efectivo hasta ser cobrados. El cobro ponderado ajusta por probabilidad.
A4: ID | B4: Cliente | C4: Servicio / proyecto | D4: Código servicio | E4: Honorarios totales ($) | F4: Cobrado ($) | G4: Saldo pendiente ($) | H4: Estado | I4: Mes esperado | J4: Probabilidad | K4: Cobro ponderado ($) | L4: Próxima acción
A5: CAR-001 | B5: Ligia Carmona | C5: Compraventa e hipoteca | D5: AGL-NOT-INM-001 | E5: 350 | F5: 0 | G5: 350 | H5: En ejecución | I5: Julio | J5: 0.9 | K5: =G5*J5 -> 315 | L5: Finalizar documentos y gestionar cobro
A6: CAR-002 | B6: Ingrid Moreno | C6: Compraventa | D6: AGL-NOT-INM-001 | E6: 350 | F6: 0 | G6: 350 | H6: En ejecución | I6: Julio | J6: 0.9 | K6: =G6*J6 -> 315 | L6: Finalizar e inscribir
A7: CAR-003 | B7: Inocencia Villatoro | C7: Compraventa | D7: AGL-NOT-INM-001 | E7: 250 | F7: 0 | G7: 250 | H7: En ejecución | I7: Julio | J7: 0.85 | K7: =G7*J7 -> 212.5 | L7: Completar expediente
A8: CAR-004 | B8: Inocencia Canales | C8: Compraventa de terreno | D8: AGL-NOT-INM-001 | E8: 0 | F8: 0 | G8: 0 | H8: Pendiente de cotización | I8: Agosto | J8: 0.5 | K8: =G8*J8 -> 0 | L8: Definir honorarios
A9: CAR-005 | B9: Magdalena Wrobel | C9: Contrato | D9: AGL-CON-CIV-001 | E9: 150 | F9: 0 | G9: 150 | H9: En ejecución | I9: Julio | J9: 0.85 | K9: =G9*J9 -> 127.5 | L9: Finalizar y cobrar
A10: CAR-006 | B10: David Juárez | C10: Remedición - primer 50% | D10: AGL-NOT-DIL-002 | E10: 350 | F10: 175 | G10: 175 | H10: En ejecución | I10: Julio | J10: 0.95 | K10: =G10*J10 -> 166.25 | L10: Cobrar segundo 50%
A11: CAR-007 | B11: David Juárez | C11: Aceptación de herencia | D11: AGL-NOT-PAT-002 | E11: 1500 | F11: 200 | G11: 1300 | H11: En ejecución | I11: Agosto | J11: 0.9 | K11: =G11*J11 -> 1170 | L11: Corrección: $200 cobrado, $1,300 pendiente
A12: CAR-008 | B12: Christine Miranda | C12: Pago final aceptación de herencia | D12: AGL-NOT-PAT-002 | E12: 750 | F12: 0 | G12: 750 | H12: En ejecución | I12: Julio | J12: 0.95 | K12: =G12*J12 -> 712.5 | L12: Finalizar para cobrar
A13: CAR-009 | B13: Christine Miranda | C13: Fee mensual por horas | E13: 0 | F13: 0 | G13: 0 | H13: Pendiente de cuantificar | I13: Agosto | J13: 0.6 | K13: =G13*J13 -> 0 | L13: Registrar horas y emitir cobro

Sheet 06_Personal
A1: 06 | Salarios y honorarios mensuales
A2: Salarios objetivo que AG Legal debe cubrir desde julio hasta diciembre de 2026.
A4: Código | B4: Persona | C4: Cargo | D4: Monto mensual ($) | E4: Mes inicio | F4: Mes fin | G4: Meses 2026 | H4: Costo Jul-Dic ($)
A5: PER-001 | B5: Guadalupe Sánchez | C5: Abogada asociada | D5: 550 | E5: 7 | F5: 12 | G5: 6 | H5: =D5*G5 -> 3300
A6: PER-002 | B6: Alfredo Gallegos | C6: Abogado y notario | D6: 550 | E6: 7 | F6: 12 | G6: 6 | H6: =D6*G6 -> 3300
A7: PER-003 | B7: Andrea Escobar | C7: Manager / Desarrollo de Negocios | D7: 250 | E7: 7 | F7: 12 | G7: 6 | H7: =D7*G7 -> 1500
A9: Indicador | B9: Mensual | C9: Jul-Dic
A10: Total salarios | B10: =SUM(D5:D7) -> 1350 | C10: =SUM(H5:H7) -> 8100

Sheet 07_Gastos_Fijos
A1: 07 | Gastos fijos y supuestos
A2: Los valores en azul son editables. El modelo parte de los costos identificados en julio.
A4: Código | B4: Concepto | C4: Tipo | D4: Monto mensual ($) | E4: Mes inicio | F4: Mes fin | G4: Meses | H4: Costo Jul-Dic ($)
A5: GF-001 | B5: Salarios | C5: Fijo | D5: 1350 | E5: 7 | F5: 12 | G5: 6 | H5: =D5*G5 -> 8100
A6: GF-002 | B6: Arrendamiento local | C6: Fijo | D6: 575 | E6: 7 | F6: 12 | G6: 6 | H6: =D6*G6 -> 3450
A7: GF-003 | B7: Internet | C7: Fijo | D7: 30 | E7: 7 | F7: 12 | G7: 6 | H7: =D7*G7 -> 180
A8: GF-004 | B8: Otros gastos administrativos | C8: Estimado | D8: 150 | E8: 7 | F8: 12 | G8: 6 | H8: =D8*G8 -> 900
A9: GF-005 | B9: Marketing y captación | C9: Meta | D9: 150 | E9: 8 | F9: 12 | G9: 5 | H9: =D9*G9 -> 750
A11: Supuesto variable | B11: Valor
A12: Costo directo variable sobre ventas | B12: 0.1
A13: Margen operativo meta | B13: 0.2
A14: Margen de seguridad sobre punto de equilibrio | B14: 0.15
A16: Compensación variable | B16: Tratamiento | C16: Base | D16: Tasa | E16: Reconocimiento | F16: Clasificación | G16: Incluida en punto de equilibrio | H16: Observación
A17: Comisión Andrea | B17: Costo variable comercial | C17: Utilidad directa cobrada | D17: 5%-15% | E17: Al cobrar | F17: Variable | G17: No | H17: Debe calcularse en el sistema, no como gasto fijo
A18: Salario Andrea | B18: Costo fijo | C18: Mensual | D18: $250 | E18: Mensual | F18: Fijo | G18: Sí | H18: Ya incluido en salarios
A19: Regla | B19: No proyectar comisión sobre honorarios contratados o cartera no cobrada

Sheet 08_Presupuesto_Jul_Dic
A1: 08 | Proyección comercial por tipo de servicio | Julio–Diciembre 2026
A2: La proyección se construye por familias de servicios: volumen esperado × ticket objetivo. No se distribuyen ventas por persona. Los salarios se tratan únicamente como costos fijos.
A4: Código familia | B4: Familia de servicios | C4: Servicios incluidos | D4: Casos históricos | E4: Ingresos históricos ($) | F4: Ticket histórico ($) | G4: Ticket objetivo ($) | H4: Margen directo estimado % | I4: Jul Cant. | J4: Jul Ingreso ($) | K4: Ago Cant. | L4: Ago Ingreso ($) | M4: Sep Cant. | N4: Sep Ingreso ($) | O4: Oct Cant. | P4: Oct Ingreso ($) | Q4: Nov Cant. | R4: Nov Ingreso ($) | S4: Dic Cant. | T4: Dic Ingreso ($) | U4: Total casos | V4: Total ingresos ($)
A5: FAM-01 | B5: Notariales rápidos | C5: Actas, auténticas, declaraciones, autorizaciones, certificaciones y compraventas de vehículo | D5: 18 | E5: 430 | F5: 23.89 | G5: 35 | H5: 0.85 | I5: 4 | J5: 140 | K5: 10 | L5: =K5*$G5 -> 350 | M5: 11 | N5: =M5*$G5 -> 385 | O5: 12 | P5: =O5*$G5 -> 420 | Q5: 13 | R5: =Q5*$G5 -> 455 | S5: 14 | T5: =S5*$G5 -> 490 | U5: =SUM(I5,K5,M5,O5,Q5,S5) -> 64 | V5: =SUM(J5,L5,N5,P5,R5,T5) -> 2240
A6: FAM-02 | B6: Asesorías, contratos y gestiones | C6: Asesorías, escritos, arrendamientos, revisión contractual y acompañamientos administrativos | D6: 20 | E6: 1480 | F6: 74 | G6: 85 | H6: 0.9 | I6: 4 | J6: 340 | K6: 8 | L6: =K6*$G6 -> 680 | M6: 9 | N6: =M6*$G6 -> 765 | O6: 9 | P6: =O6*$G6 -> 765 | Q6: 10 | R6: =Q6*$G6 -> 850 | S6: 10 | T6: =S6*$G6 -> 850 | U6: =SUM(I6,K6,M6,O6,Q6,S6) -> 50 | V6: =SUM(J6,L6,N6,P6,R6,T6) -> 4250
A7: FAM-03 | B7: Inmobiliario y registral | C7: Compraventas de inmueble, promesas, hipotecas, investigaciones registrales y remediciones | D7: 9 | E7: 830 | F7: 92.22 | G7: 300 | H7: 0.88 | I7: 5 | J7: 1300 | K7: 3 | L7: =K7*$G7 -> 900 | M7: 3 | N7: =M7*$G7 -> 900 | O7: 3 | P7: =O7*$G7 -> 900 | Q7: 3 | R7: =Q7*$G7 -> 900 | S7: 4 | T7: =S7*$G7 -> 1200 | U7: =SUM(I7,K7,M7,O7,Q7,S7) -> 21 | V7: =SUM(J7,L7,N7,P7,R7,T7) -> 6100
A8: FAM-04 | B8: Herencias y planificación patrimonial | C8: Aceptaciones de herencia, cesiones de derechos, publicaciones y trámites sucesorios | D8: 4 | E8: 250 | F8: 62.5 | G8: 750 | H8: 0.82 | I8: 1 | J8: 750 | K8: 2 | L8: =K8*$G8 -> 1500 | M8: 1 | N8: =M8*$G8 -> 750 | O8: 1 | P8: =O8*$G8 -> 750 | Q8: 1 | R8: =Q8*$G8 -> 750 | S8: 1 | T8: =S8*$G8 -> 750 | U8: =SUM(I8,K8,M8,O8,Q8,S8) -> 7 | V8: =SUM(J8,L8,N8,P8,R8,T8) -> 5250
A9: FAM-05 | B9: Corporativo y administrativo especializado | C9: Protocolizaciones, OPAMSS, trámites complejos, conciliaciones y servicios empresariales | D9: 5 | E9: 650 | F9: 130 | G9: 350 | H9: 0.88 | I9: 1 | J9: 350 | K9: 1 | L9: =K9*$G9 -> 350 | M9: 1 | N9: =M9*$G9 -> 350 | O9: 1 | P9: =O9*$G9 -> 350 | Q9: 1 | R9: =Q9*$G9 -> 350 | S9: 1 | T9: =S9*$G9 -> 350 | U9: =SUM(I9,K9,M9,O9,Q9,S9) -> 6 | V9: =SUM(J9,L9,N9,P9,R9,T9) -> 2100
A10: FAM-06 | B10: Migración, relocalización y servicios internacionales | C10: NIT, residencias, acompañamiento migratorio, traducciones y relocalización | D10: 2 | E10: 945 | F10: 472.5 | G10: 500 | H10: 0.82 | I10: 0 | J10: 0 | K10: 1 | L10: =K10*$G10 -> 500 | M10: 1 | N10: =M10*$G10 -> 500 | O10: 1 | P10: =O10*$G10 -> 500 | Q10: 1 | R10: =Q10*$G10 -> 500 | S10: 1 | T10: =S10*$G10 -> 500 | U10: =SUM(I10,K10,M10,O10,Q10,S10) -> 5 | V10: =SUM(J10,L10,N10,P10,R10,T10) -> 2500
A11: TOTAL PROYECCIÓN POR SERVICIOS | D11: =SUM(D5:D10) -> 58 | E11: =SUM(E5:E10) -> 4585 | F11: =IFERROR(E11/D11,0) -> 79.051724 | G11: =IFERROR(V11/U11,0) -> 146.66667 | H11: =SUMPRODUCT(V5:V10,H5:H10)/V11 -> 0.8600713 | I11: =SUM(I5:I10) -> 15 | J11: =SUM(J5:J10) -> 2880 | K11: =SUM(K5:K10) -> 25 | L11: =SUM(L5:L10) -> 4280 | M11: =SUM(M5:M10) -> 26 | N11: =SUM(N5:N10) -> 3650 | O11: =SUM(O5:O10) -> 27 | P11: =SUM(P5:P10) -> 3685 | ... V11: =SUM(V5:V10) -> 22440
A14: Resultado mensual | B14: Julio | C14: Agosto | D14: Septiembre | E14: Octubre | F14: Noviembre | G14: Diciembre
A15: Ingresos proyectados por servicios | B15: =J$11 -> 2880 | C15: =L$11 -> 4280 | D15: =N$11 -> 3650 | E15: =P$11 -> 3685 | F15: =R$11 -> 3805 | G15: =T$11 -> 4140
A16: Costos directos estimados | B16: =SUMPRODUCT(J$5:J$10,1-$H$5:$H$10) -> 388 | C16: =SUMPRODUCT(L$5:L$10,1-$H$5:$H$10) -> 630.5 | D16: =SUMPRODUCT(N$5:N$10,1-$H$5:$H$10) -> 509.25 | E16: =SUMPRODUCT(P$5:P$10,1-$H$5:$H$10) -> 514.5 | F16: =SUMPRODUCT(R$5:R$10,1-$H$5:$H$10) -> 528.25 | G16: =SUMPRODUCT(T$5:T$10,1-$H$5:$H$10) -> 569.5
A17: Margen de contribución | B17: =B15-B16 -> 2492 | C17: =C15-C16 -> 3649.5 | D17: =D15-D16 -> 3140.75 | E17: =E15-E16 -> 3170.5 | F17: =F15-F16 -> 3276.75 | G17: =G15-G16 -> 3570.5
A18: Gastos fijos mensuales | B18: =SUM('07_Gastos_Fijos'!$D$5:$D$9) -> 2255 | C18: =SUM('07_Gastos_Fijos'!$D$5:$D$9) -> 2255 | D18: =SUM('07_Gastos_Fijos'!$D$5:$D$9) -> 2255 | E18: =SUM('07_Gastos_Fijos'!$D$5:$D$9) -> 2255 | F18: =SUM('07_Gastos_Fijos'!$D$5:$D$9) -> 2255 | G18: =SUM('07_Gastos_Fijos'!$D$5:$D$9) -> 2255
A19: Utilidad operativa | B19: =B17-B18 -> 237 | C19: =C17-C18 -> 1394.5 | D19: =D17-D18 -> 885.75 | E19: =E17-E18 -> 915.5 | F19: =F17-F18 -> 1021.75 | G19: =G17-G18 -> 1315.5
A20: Margen operativo % | B20: =IFERROR(B19/B15,0) -> 0.082291667 | C20: =IFERROR(C19/C15,0) -> 0.32581776 | D20: =IFERROR(D19/D15,0) -> 0.24267123 | E20: =IFERROR(E19/E15,0) -> 0.24843962 | F20: =IFERROR(F19/F15,0) -> 0.26852825 | G20: =IFERROR(G19/G15,0) -> 0.31775362
A21: Diferencia vs. punto de equilibrio | B21: =B15-'09_Punto_Equilibrio'!$B$7 -> 374.44444 | C21: =C15-'09_Punto_Equilibrio'!$B$7 -> 1774.4444 | D21: =D15-'09_Punto_Equilibrio'!$B$7 -> 1144.4444 | E21: =E15-'09_Punto_Equilibrio'!$B$7 -> 1179.4444 | F21: =F15-'09_Punto_Equilibrio'!$B$7 -> 1299.4444 | G21: =G15-'09_Punto_Equilibrio'!$B$7 -> 1634.4444

Sheet 09_Punto_Equilibrio
A1: 09 | Punto de equilibrio y metas mínimas
A2: Calcula cuánto debe cobrarse mensualmente para cubrir costos y generar utilidad.
A4: Indicador | B4: Resultado
A5: Gastos fijos mensuales | B5: =SUM('07_Gastos_Fijos'!D5:D9) -> 2255
A6: Costo variable % | B6: ='07_Gastos_Fijos'!B12 -> 0.1
A7: Punto de equilibrio de ventas | B7: =B5/(1-B6) -> 2505.5556
A8: Meta con margen de seguridad | B8: =B7*(1+'07_Gastos_Fijos'!B14) -> 2881.3889
A9: Ventas para margen operativo meta | B9: =B5/(1-B6-'07_Gastos_Fijos'!B13) -> 3221.4286
A10: Salarios cubiertos por las ventas meta | B10: =B9/'06_Personal'!B10 -> 2.3862434
A12: Ejemplo de mezcla mínima | B12: Cantidad | C12: Ticket promedio ($) | D12: Ingresos ($) | E12: Objetivo | F12: Comentario
A13: Servicios rápidos notariales | B13: 10 | C13: 35 | D13: =B13*C13 -> 350 | E13: Flujo inmediato | F13: Poderes, auténticas, declaraciones
A14: Contratos / asesorías | B14: 8 | C14: 75 | D14: =B14*C14 -> 600 | E14: Frecuencia | F14: Contratos, revisiones y acompañamientos
A15: Operaciones inmobiliarias | B15: 3 | C15: 300 | D15: =B15*C15 -> 900 | E15: Margen | F15: Compraventas, hipotecas y promesas
A16: Herencia / proceso de mayor valor | B16: 1 | C16: 750 | D16: =B16*C16 -> 750 | E16: Ticket alto | F16: Cobro por etapas
A17: TOTAL | D17: =SUM(D13:D16) -> 2600

Sheet 10_Dashboard
A1: 10 | Dashboard ejecutivo
A2: Vista rápida de cobros, cartera, punto de equilibrio y utilidad proyectada.
A4: COBRADO MAR-JUL | E4: CARTERA PENDIENTE | I4: PUNTO DE EQUILIBRIO | M4: META SEGURA
A5: =SUMIFS('04_Registro_Operaciones'!$F$5:$F$300,'04_Registro_Operaciones'!$E$5:$E$300,"Ingreso") -> 5515.5 | E5: =SUM('05_Cartera_Proyectos'!$G$5:$G$100) -> 3325 | I5: ='09_Punto_Equilibrio'!B7 -> 2505.5556 | M5: ='09_Punto_Equilibrio'!B8 -> 2881.3889
A9: Mes | B9: Ingresos proyectados ($) | C9: Utilidad operativa ($)
A10: Julio | B10: ='08_Presupuesto_Jul_Dic'!B15 -> 2880 | C10: ='08_Presupuesto_Jul_Dic'!B19 -> 237
A11: Agosto | B11: ='08_Presupuesto_Jul_Dic'!C15 -> 4280 | C11: ='08_Presupuesto_Jul_Dic'!C19 -> 1394.5
A12: Septiembre | B12: ='08_Presupuesto_Jul_Dic'!D15 -> 3650 | C12: ='08_Presupuesto_Jul_Dic'!D19 -> 885.75
A13: Octubre | B13: ='08_Presupuesto_Jul_Dic'!E15 -> 3685 | C13: ='08_Presupuesto_Jul_Dic'!E19 -> 915.5
A14: Noviembre | B14: ='08_Presupuesto_Jul_Dic'!F15 -> 3805 | C14: ='08_Presupuesto_Jul_Dic'!F19 -> 1021.75
A15: Diciembre | B15: ='08_Presupuesto_Jul_Dic'!G15 -> 4140 | C15: ='08_Presupuesto_Jul_Dic'!G19 -> 1315.5
A27: REQUERIMIENTOS PARA IMPLEMENTACIÓN EN EL SISTEMA
A28: Indicador | B28: Fuente | C28: Cálculo | D28: Actualización | E28: Filtro mínimo | F28: Drill-down
A29: Cumplimiento ingresos | B29: Cobros + forecast | C29: Ingresos cobrados / meta | D29: Automática | E29: Mes, categoría | F29: Expedientes
A30: Cumplimiento casos | B30: Expedientes + forecast | C30: Casos reales / meta casos | D30: Automática | E30: Mes, familia | F30: Servicios
A31: Utilidad operativa | B31: Cobros + costos + gastos + comisión | C31: Ingresos - costos - gastos - comisión | D31: Automática | E31: Mes | F31: P&L
A32: Comisión Andrea | B32: Origen + cobro + utilidad directa | C32: Escala 10%-12%-15% o 5% cross-sell | D32: Automática al cobrar | E32: Mes, expediente | F32: Detalle de comisión
A33: Servicios frecuentes/rentables | B33: Expedientes + cobros | C33: Frecuencia, utilidad directa y margen | D33: Automática | E33: Categoría, servicio | F33: Código servicio
A36: RESUMEN DE CUMPLIMIENTO MENSUAL
A37: Mes | B37: Meta ingresos | C37: Ingresos reales | D37: Cumplimiento | E37: Utilidad operativa real | F37: Utilidad mínima | G37: Semáforo
A38: ='17_Resumen_Mensual'!A5 -> Julio | B38: ='17_Resumen_Mensual'!B5 -> 3080 | C38: ='17_Resumen_Mensual'!C5 -> 350 | D38: ='17_Resumen_Mensual'!D5 -> 0.11363636 | E38: ='17_Resumen_Mensual'!J5 -> -1905 | F38: ='17_Resumen_Mensual'!K5 -> 616 | G38: ='17_Resumen_Mensual'!O5 -> ROJO
A39: ='17_Resumen_Mensual'!A6 -> Agosto | B39: ='17_Resumen_Mensual'!B6 -> 4280 | C39: ='17_Resumen_Mensual'!C6 -> 0 | D39: ='17_Resumen_Mensual'!D6 -> 0 | E39: ='17_Resumen_Mensual'!J6 -> -2255 | F39: ='17_Resumen_Mensual'!K6 -> 856 | G39: ='17_Resumen_Mensual'!O6 -> ROJO
A40: ='17_Resumen_Mensual'!A7 -> Septiembre | B40: ='17_Resumen_Mensual'!B7 -> 3650 | C40: ='17_Resumen_Mensual'!C7 -> 0 | D40: ='17_Resumen_Mensual'!D7 -> 0 | E40: ='17_Resumen_Mensual'!J7 -> -2255 | F40: ='17_Resumen_Mensual'!K7 -> 730 | G40: ='17_Resumen_Mensual'!O7 -> ROJO
A41: ='17_Resumen_Mensual'!A8 -> Octubre | B41: ='17_Resumen_Mensual'!B8 -> 3685 | C41: ='17_Resumen_Mensual'!C8 -> 0 | D41: ='17_Resumen_Mensual'!D8 -> 0 | E41: ='17_Resumen_Mensual'!J8 -> -2255 | F41: ='17_Resumen_Mensual'!K8 -> 737 | G41: ='17_Resumen_Mensual'!O8 -> ROJO
A42: ='17_Resumen_Mensual'!A9 -> Noviembre | B42: ='17_Resumen_Mensual'!B9 -> 3805 | C42: ='17_Resumen_Mensual'!C9 -> 0 | D42: ='17_Resumen_Mensual'!D9 -> 0 | E42: ='17_Resumen_Mensual'!J9 -> -2255 | F42: ='17_Resumen_Mensual'!K9 -> 761 | G42: ='17_Resumen_Mensual'!O9 -> ROJO
A43: ='17_Resumen_Mensual'!A10 -> Diciembre | B43: ='17_Resumen_Mensual'!B10 -> 4140 | C43: ='17_Resumen_Mensual'!C10 -> 0 | D43: ='17_Resumen_Mensual'!D10 -> 0 | E43: ='17_Resumen_Mensual'!J10 -> -2255 | F43: ='17_Resumen_Mensual'!K10 -> 828 | G43: ='17_Resumen_Mensual'!O10 -> ROJO

Sheet 11_Listas
A1: 11 | Listas de control
A2: Valores auxiliares para el sistema.
A4: Estado servicio | B4: Unidad cobro | C4: Estado cartera | D4: Mes | E4: Tipo operación | F4: Responsable
A5: Activo | B5: Precio fijo | C5: Pendiente de cotización | D5: Julio | E5: Ingreso | F5: Socio / Notario
A6: Inactivo | B6: Por hora | C6: Pendiente de cuantificar | D6: Agosto | E6: Egreso | F6: Abogada asociada
A7: En diseño | B7: Por etapa | C7: En ejecución | D7: Septiembre | F7: Manager
B8: Mensual | C8: Finalizado pendiente de facturar | D8: Octubre | F8: Asistente legal
B9: Porcentaje | C9: Facturado pendiente de cobro | D9: Noviembre | F9: Equipo mixto
B10: Por definir | C10: Cobrado | D10: Diciembre | F10: Por definir
C11: Suspendido

Sheet 12_Reglas_Comision
A1: 12 | Reglas de compensación variable de Comercial
A2: La compensación se calcula únicamente sobre utilidad directa efectivamente cobrada de negocios originados o ampliados por Andrea.
A4: Regla ID | B4: Tipo de negocio | C4: Condición | D4: Base de cálculo | E4: Tramo desde ($) | F4: Tramo hasta ($) | G4: Porcentaje | H4: Momento de reconocimiento | I4: Exclusiones | J4: Responsable de validación | K4: Estado
A5: COM-001 | B5: Cliente nuevo originado y cerrado por Andrea | C5: Andrea identifica, desarrolla, cotiza o coordina la propuesta y logra la aceptación del cliente. | D5: Utilidad directa cobrada | E5: 0 | F5: 1000 | G5: 0.1 | H5: Al cobrarse efectivamente el honorario | I5: IVA, tasas, publicaciones, derechos registrales, gastos reembolsables, fondos de terceros y devoluciones | J5: Administración / Socio | K5: Activo
A6: COM-002 | B6: Cliente nuevo originado y cerrado por Andrea | C6: Segundo tramo mensual acumulado de utilidad directa originada. | D6: Utilidad directa cobrada | E6: 1000.01 | F6: 2500 | G6: 0.12 | H6: Al cobrarse efectivamente el honorario | I6: IVA, tasas, publicaciones, derechos registrales, gastos reembolsables, fondos de terceros y devoluciones | J6: Administración / Socio | K6: Activo
A7: COM-003 | B7: Cliente nuevo originado y cerrado por Andrea | C7: Tercer tramo mensual acumulado de utilidad directa originada. | D7: Utilidad directa cobrada | E7: 2500.01 | F7: 9999999 | G7: 0.15 | H7: Al cobrarse efectivamente el honorario | I7: IVA, tasas, publicaciones, derechos registrales, gastos reembolsables, fondos de terceros y devoluciones | J7: Administración / Socio | K7: Activo
A8: COM-004 | B8: Venta cruzada a cliente existente | C8: Andrea genera y cierra un servicio adicional para un cliente ya perteneciente a AG Legal. | D8: Utilidad directa cobrada | E8: 0 | F8: 9999999 | G8: 0.05 | H8: Al cobrarse efectivamente el honorario | I8: Servicios ya contratados, renovaciones automáticas y simples seguimientos administrativos | J8: Administración / Socio | K8: Activo
A10: Concepto | B10: Definición funcional
A11: Honorario cobrado | B11: Importe neto efectivamente recibido por AG Legal por el servicio.
A12: Costo directo | B12: Costo atribuible al expediente: terceros, gestor, transporte específico, traducción, publicación o insumo particular.
A13: Utilidad directa | B13: Honorario cobrado menos costo directo atribuible al servicio.
A14: Negocio originado | B14: Cliente o asunto nuevo conseguido por Andrea y registrado con evidencia de origen.
A15: Venta cruzada | B15: Servicio nuevo vendido a un cliente existente de la firma.
A16: Fecha de comisión | B16: Mes en el que el efectivo se recibe, no la fecha de cotización o contratación.
A17: Reversión | B17: Si existe devolución o ajuste posterior, la comisión se corrige en el siguiente período.
A19: Ejemplo | B19: Utilidad directa mensual ($) | C19: 10% tramo 1 | D19: 12% tramo 2 | E19: 15% tramo 3 | F19: Comisión total ($)
A20: Caso A | B20: 600 | C20: =MIN(B20,1000)*10% -> 60 | D20: =MAX(MIN(B20-1000,1500),0)*12% -> 0 | E20: =MAX(B20-2500,0)*15% -> 0 | F20: =SUM(C20:E20) -> 60
A21: Caso B | B21: 1800 | C21: =MIN(B21,1000)*10% -> 100 | D21: =MAX(MIN(B21-1000,1500),0)*12% -> 96 | E21: =MAX(B21-2500,0)*15% -> 0 | F21: =SUM(C21:E21) -> 196
A22: Caso C | B22: 3000 | C22: =MIN(B22,1000)*10% -> 100 | D22: =MAX(MIN(B22-1000,1500),0)*12% -> 180 | E22: =MAX(B22-2500,0)*15% -> 75 | F22: =SUM(C22:E22) -> 355
A23: Caso D | B23: 4500 | C23: =MIN(B23,1000)*10% -> 100 | D23: =MAX(MIN(B23-1000,1500),0)*12% -> 180 | E23: =MAX(B23-2500,0)*15% -> 300 | F23: =SUM(C23:E23) -> 580
A24: Fórmula de referencia | B24: MIN(U,1000)*10% + MAX(MIN(U-1000,1500),0)*12% + MAX(U-2500,0)*15%

Sheet 13_Especificacion_Sistema
A1: 13 | ANEXO TÉCNICO — consultar después de 00_PARA_DESARROLLADOR
A2: Esta hoja conserva el detalle ampliado de campos. La hoja principal y obligatoria para iniciar la implementación es 00_PARA_DESARROLLADOR.
A4: Módulo | B4: Entidad / tabla | C4: Campo | D4: Tipo de dato | E4: Obligatorio | F4: Editable | G4: Fuente / relación | H4: Regla de validación | I4: Cálculo automático | J4: Uso en dashboard | K4: Histórico requerido | L4: Ejemplo | M4: Prioridad | N4: Observaciones
A5: Catálogo | B5: categorias | C5: codigo_categoria | D5: Texto 3-4 | E5: Sí | F5: No | G5: Maestro | H5: Único, mayúsculas, no reutilizable | J5: Filtro y agrupación | K5: Sí | L5: NOT | M5: Alta | N5: Clave primaria funcional
A6: Catálogo | B6: categorias | C6: nombre_categoria | D6: Texto | E6: Sí | F6: Sí | G6: Maestro | H6: Nombre único | J6: Etiqueta | K6: Sí | L6: Servicios Notariales | M6: Alta
A7: Catálogo | B7: subcategorias | C7: codigo_subcategoria | D7: Texto 3 | E7: Sí | F7: No | G7: Depende de categoría | H7: Único dentro de categoría | J7: Filtro y agrupación | K7: Sí | L7: INM | M7: Alta
A8: Catálogo | B8: servicios | C8: codigo_servicio | D8: Texto | E8: Sí | F8: No | G8: Categoría + subcategoría + secuencia | H8: Formato AGL-CAT-SUB-000 | J8: Búsqueda y drill-down | K8: Sí | L8: AGL-NOT-INM-001 | M8: Crítica | N8: Nunca reutilizar
A9: Catálogo | B9: servicios | C9: nombre_servicio | D9: Texto | E9: Sí | F9: Sí | G9: Maestro | H9: No duplicar prestación idéntica | J9: Ranking servicios | K9: Sí | L9: Escritura de compraventa | M9: Crítica
A10: Catálogo | B10: servicios | C10: etiquetas | D10: Texto múltiple | E10: No | F10: Sí | G10: Maestro | H10: Separadas por coma | J10: Búsqueda transversal | K10: Sí | L10: familia, inmueble, notarial | M10: Media
A11: Operaciones | B11: expedientes | C11: id_expediente | D11: Autonumérico | E11: Sí | F11: No | G11: Sistema | H11: Único | J11: Conteo casos | K11: Sí | L11: EXP-2026-0001 | M11: Crítica
A12: Operaciones | B12: expedientes | C12: cliente_id | D12: Relación | E12: Sí | F12: Sí | G12: Clientes | H12: Cliente válido | J12: Clientes nuevos/recurrentes | K12: Sí | L12: CLI-001 | M12: Crítica
A13: Operaciones | B13: expedientes | C13: codigo_servicio | D13: Relación | E13: Sí | F13: Sí | G13: Catálogo servicios | H13: Solo servicios activos | I13: Completa categoría y subcategoría | J13: Ventas por servicio | K13: Sí | L13: AGL-NOT-INM-001 | M13: Crítica
A14: Operaciones | B14: expedientes | C14: origen_negocio | D14: Lista | E14: Sí | F14: Sí | G14: Lista control | H14: Andrea / Alfredo / Guadalupe / Referido / Orgánico / Otro | J14: Ventas por origen | K14: Sí | L14: Andrea | M14: Crítica | N14: Base de comisión
A15: Operaciones | B15: expedientes | C15: tipo_origen | D15: Lista | E15: Sí | F15: Sí | G15: Lista control | H15: Cliente nuevo / Venta cruzada / Cliente existente | J15: Conversión y comisión | K15: Sí | L15: Cliente nuevo | M15: Crítica
A16: Operaciones | B16: expedientes | C16: honorarios_contratados | D16: Moneda | E16: Sí | F16: Sí | G16: Contrato/propuesta | H16: Mayor o igual a cero | J16: Pipeline y ticket | K16: Sí | L16: 750 | M16: Crítica | N16: Excluir IVA y reembolsos
A17: Operaciones | B17: expedientes | C17: costos_directos_estimados | D17: Moneda | E17: Sí | F17: Sí | G17: Presupuesto expediente | H17: Mayor o igual a cero | I17: Utilidad directa estimada | J17: Margen proyectado | K17: Sí | L17: 70 | M17: Alta
A18: Operaciones | B18: expedientes | C18: estado_expediente | D18: Lista | E18: Sí | F18: Sí | G18: Workflow | H18: Cotizado / Aceptado / En ejecución / Finalizado / Facturado / Cobrado / Suspendido | J18: Pipeline | K18: Sí | L18: En ejecución | M18: Crítica
A19: Operaciones | B19: expedientes | C19: mes_cobro_esperado | D19: Fecha mes | E19: Sí | F19: Sí | G19: Gestión | H19: No anterior a fecha de apertura | I19: Proyección mensual | J19: Forecast | K19: Sí | L19: 2026-08 | M19: Crítica
A20: Cobros | B20: cobros | C20: monto_honorario_cobrado | D20: Moneda | E20: Sí | F20: Sí | G20: Expediente | H20: No incluir IVA ni gastos de terceros | I20: Saldo pendiente | J20: Ingresos cobrados | K20: Sí | L20: 200 | M20: Crítica
A21: Cobros | B21: cobros | C21: fecha_cobro | D21: Fecha | E21: Sí | F21: Sí | G21: Banco/caja | H21: Fecha válida | I21: Mes real de ingreso | J21: Cumplimiento mensual | K21: Sí | L21: 2026-07-15 | M21: Crítica
A22: Cobros | B22: cobros | C22: monto_costo_directo_real | D22: Moneda | E22: Sí | F22: Sí | G22: Expediente | H22: Mayor o igual a cero | I22: Utilidad directa real | J22: Margen real | K22: Sí | L22: 25 | M22: Crítica
A23: Cobros | B23: cobros | C23: utilidad_directa_real | D23: Moneda | E23: Sí | F23: No | G23: Cobro - costo directo | H23: Puede ser negativa | I23: Honorario neto - costo directo | J23: Comisión y rentabilidad | K23: Sí | L23: 175 | M23: Crítica
A24: Comisión | B24: comisiones | C24: elegible_comision_andrea | D24: Booleano | E24: Sí | F24: Sí | G24: Origen y tipo de negocio | H24: Debe existir evidencia del origen | I24: Sí/No por reglas | J24: Comisión devengada | K24: Sí | L24: Sí | M24: Crítica
A25: Comisión | B25: comisiones | C25: porcentaje_aplicable | D25: Porcentaje | E25: Sí | F25: No | G25: Reglas COM-001 a COM-004 | H25: 5%, 10%, 12% o 15% | I25: Escalonado por mes | J25: Costo variable | K25: Sí | L25: 10% | M25: Crítica
A26: Comisión | B26: comisiones | C26: comision_devengada | D26: Moneda | E26: Sí | F26: No | G26: Utilidad directa cobrada | H26: Solo después del cobro | I26: Según tramos y venta cruzada | J26: Comisión mensual | K26: Sí | L26: 60 | M26: Crítica
A27: Proyección | B27: forecast | C27: volumen_meta | D27: Entero | E27: Sí | F27: Sí | G27: Familia + mes | H27: Mayor o igual a cero | I27: Volumen × ticket objetivo | J27: Cumplimiento de volumen | K27: Sí | L27: 3 | M27: Alta
A28: Proyección | B28: forecast | C28: ticket_objetivo | D28: Moneda | E28: Sí | F28: Sí | G28: Familia + mes | H28: Mayor o igual a cero | I28: Ingreso meta | J28: Cumplimiento de ingresos | K28: Sí | L28: 300 | M28: Alta
A29: Proyección | B29: forecast | C29: ingreso_proyectado | D29: Moneda | E29: Sí | F29: No | G29: Volumen × ticket | H29: Fórmula automática | I29: volumen_meta*ticket_objetivo | J29: Forecast mensual | K29: Sí | L29: 900 | M29: Crítica
A30: Proyección | B30: forecast | C30: probabilidad_cobro | D30: Porcentaje | E30: Sí | F30: Sí | G30: Estado expediente | H30: 0% a 100% | I30: Saldo pendiente × probabilidad | J30: Forecast ponderado | K30: Sí | L30: 90% | M30: Alta
A34: REQUISITOS ADICIONALES: PLAN DE CUENTAS Y MOVIMIENTOS
A35: Finanzas | B35: plan_cuentas | C35: codigo_cuenta | D35: Texto | E35: Sí | F35: No | G35: Plan de cuentas | H35: Único; formato ING-XXX-000 o EGR-XXX-000 | J35: Agrupación de ingresos y egresos | K35: Sí | L35: ING-RAI-001 | M35: Crítica | N35: Todo movimiento debe tener código de cuenta.
A36: Finanzas | B36: movimientos | C36: tipo_movimiento | D36: Lista | E36: Sí | F36: Sí | G36: Ingreso / Egreso | H36: Debe coincidir con el prefijo de código cuenta | J36: P&L y flujo | K36: Sí | L36: Ingreso | M36: Crítica | N36: ING solo para ingresos; EGR solo para egresos.
A37: Finanzas | B37: movimientos | C37: codigo_cuenta | D37: Relación | E37: Sí | F37: Sí | G37: Plan de cuentas | H37: Cuenta activa y compatible con tipo de movimiento | I37: Completa cuenta, grupo y centro de costo | J37: P&L por cuenta | K37: Sí | L37: EGR-LOC-001 | M37: Crítica
A38: Finanzas | B38: movimientos | C38: codigo_servicio | D38: Relación | E38: Condicional | F38: Sí | G38: Catálogo servicios | H38: Obligatorio para ingresos jurídicos y costos directos de expediente | I38: Completa categoría y subcategoría | J38: Rentabilidad por servicio | K38: Sí | L38: AGL-RAI-RGT-001 | M38: Crítica | N38: Puede quedar vacío para salarios o renta.
A39: Finanzas | B39: movimientos | C39: monto_bruto | D39: Moneda | E39: Sí | F39: Sí | G39: Documento fuente | H39: Mayor o igual a cero | I39: Monto neto operativo | J39: Ingresos y egresos | K39: Sí | L39: 350 | M39: Crítica
A40: Finanzas | B40: movimientos | C40: monto_reembolsable | D40: Moneda | E40: Sí | F40: Sí | G40: Expediente | H40: Mayor o igual a cero | I40: Excluir de utilidad y comisión | J40: Flujo de terceros | K40: Sí | L40: 23.75 | M40: Alta
A41: Finanzas | B41: movimientos | C41: monto_neto_operativo | D41: Moneda | E41: Sí | F41: No | G41: Bruto - IVA - reembolsable | H41: Fórmula automática | I41: monto_bruto-IVA-reembolsable | J41: P&L y comisión | K41: Sí | L41: 326.25 | M41: Crítica
A44: REQUISITOS DE GOBIERNO DEL CATÁLOGO
A45: Gobierno catálogo | B45: solicitudes_catalogo | C45: id_solicitud | D45: Texto | E45: Sí | F45: No | G45: Sistema | H45: Único y secuencial | I45: Generación automática | J45: Auditoría de cambios | K45: Sí | L45: SOL-2026-001 | M45: Crítica
A46: Gobierno catálogo | B46: solicitudes_catalogo | C46: tipo_solicitud | D46: Lista | E46: Sí | F46: Sí | G46: Alta/Modificación/Inactivación | H46: Valor permitido | J46: Análisis de cambios | K46: Sí | L46: Alta | M46: Alta
...

Sheet 14_Dashboard_KPIs
A1: 14 | Requerimientos del dashboard
A2: Indicadores que el sistema debe calcular automáticamente a partir de expedientes, cobros, costos, cartera y metas.
A4: KPI ID | B4: Indicador | C4: Definición | D4: Fórmula funcional | E4: Frecuencia | F4: Filtros | G4: Visual recomendado | H4: Meta / semáforo | I4: Fuente principal | J4: Drill-down | K4: Prioridad | L4: Notas
A5: KPI-001 | B5: Ingresos cobrados | C5: Honorarios netos efectivamente recibidos en el período. | D5: SUM(monto_honorario_cobrado) | E5: Diaria / mensual | F5: Mes, categoría, subcategoría, servicio, origen | G5: Tarjeta + línea mensual | H5: Verde >= meta; amarillo 90%-99%; rojo <90% | I5: Cobros | J5: Lista de cobros | K5: Crítica | L5: Excluir IVA y reembolsos
A6: KPI-002 | B6: Ingresos proyectados | C6: Volumen meta por ticket objetivo, más cartera ponderada. | D6: SUM(volumen_meta*ticket_objetivo)+SUM(saldo_pendiente*probabilidad) | E6: Mensual | F6: Mes y familia | G6: Columnas meta vs real | H6: Comparar contra presupuesto | I6: Forecast + cartera | J6: Expedientes proyectados | K6: Crítica
A7: KPI-003 | B7: Cumplimiento de ingresos | C7: Porcentaje de ingresos cobrados contra meta mensual. | D7: Ingresos cobrados / Meta ingresos | E7: Diaria / mensual | F7: Mes, categoría | G7: Gauge o barra de progreso | H7: Verde >=100%; amarillo 85%-99%; rojo <85% | I7: Cobros + forecast | J7: Servicios del mes | K7: Crítica
A8: KPI-004 | B8: Punto de equilibrio | C8: Ventas necesarias para cubrir gastos fijos y costos variables. | D8: Gastos fijos / (1 - % costo variable) | E8: Mensual | F8: Mes | G8: Tarjeta y línea de referencia | H8: Verde si ingresos > punto equilibrio | I8: Gastos + supuestos | J8: Detalle costos | K8: Crítica
A9: KPI-005 | B9: Utilidad operativa | C9: Ingresos cobrados menos costos directos, gastos fijos y comisión. | D9: Ingresos - costos directos - gastos fijos - comisión | E9: Mensual | F9: Mes, categoría | G9: Tarjeta + tendencia | H9: Verde >0; rojo <0 | I9: Cobros + gastos + comisiones | J9: P&L mensual | K9: Crítica
A10: KPI-006 | B10: Margen operativo | C10: Utilidad operativa como porcentaje de ingresos cobrados. | D10: Utilidad operativa / Ingresos cobrados | E10: Mensual | F10: Mes, categoría | G10: Tarjeta porcentual | H10: Meta inicial 20% | I10: P&L | J10: Detalle mensual | K10: Alta
A11: KPI-007 | B11: Cartera pendiente | C11: Honorarios contratados aún no cobrados. | D11: SUM(honorarios_contratados - cobros) | E11: Diaria | F11: Estado, mes esperado, cliente | G11: Tarjeta + aging | H11: Rojo si vencida | I11: Expedientes + cobros | J11: Detalle expediente | K11: Crítica
A12: KPI-008 | B12: Cartera ponderada | C12: Saldo pendiente ajustado por probabilidad de cobro. | D12: SUM(saldo_pendiente*probabilidad) | E12: Diaria | F12: Mes esperado, estado | G12: Columnas por mes | H12: Comparar con meta | I12: Expedientes | J12: Detalle cartera | K12: Alta
A13: KPI-009 | B13: Ticket promedio | C13: Ingreso cobrado promedio por expediente o servicio. | D13: Ingresos cobrados / expedientes cobrados | E13: Mensual | F13: Categoría, servicio | G13: Tarjeta + ranking | H13: Comparar con ticket objetivo | I13: Cobros | J13: Expedientes cobrados | K13: Alta
A14: KPI-010 | B14: Servicios más frecuentes | C14: Número de expedientes por servicio. | D14: COUNT(expedientes) por código servicio | E14: Mensual | F14: Mes, categoría | G14: Top 10 barras | H14: Sin semáforo | I14: Expedientes | J14: Lista expedientes | K14: Alta
A15: KPI-011 | B15: Servicios más rentables | C15: Utilidad directa y margen por servicio. | D15: SUM(utilidad directa) y utilidad/ingreso | E15: Mensual | F15: Categoría, servicio | G15: Matriz frecuencia vs margen | H15: Priorizar alto margen y frecuencia | I15: Cobros + costos | J15: Detalle por código | K15: Crítica
A16: KPI-012 | B16: Conversión comercial | C16: Propuestas aceptadas sobre propuestas emitidas. | D16: Aceptadas / Cotizadas | E16: Mensual | F16: Origen, servicio | G16: Funnel | H16: Meta a definir | I16: Expedientes | J16: Cotizaciones | K16: Media
A17: KPI-013 | B17: Cumplimiento de volumen | C17: Casos reales contra volumen meta por familia. | D17: Casos abiertos o cobrados / volumen_meta | E17: Mensual | F17: Familia, mes | G17: Barras progreso | H17: Verde >=100% | I17: Expedientes + forecast | J17: Servicios de familia | K17: Alta
... A20: KPI-016 | B20: Días promedio de cobro | C20: Tiempo desde finalización o facturación hasta cobro. | D20: AVG(fecha_cobro - fecha_factura/finalización) | E20: Mensual | F20: Servicio, cliente | G20: Tarjeta + tendencia | H20: Menor es mejor | I20: Expedientes + cobros | J20: Aging | K20: Media

Sheet 15_Cumplimiento_Metas
A1: 15 | Metas mensuales, realidad y cumplimiento
A2: Las metas se definen por familia de servicio. Las columnas azules se llenan con la realidad mientras el sistema entra en operación; luego deberán alimentarse automáticamente.
A4: Mes | B4: Código familia | C4: Familia de servicios | D4: Meta casos | E4: Casos reales | F4: Cumplimiento casos % | G4: Ticket objetivo ($) | H4: Ticket real ($) | I4: Variación ticket % | J4: Meta ingresos ($) | K4: Ingresos reales ($) | L4: Cumplimiento ingresos % | M4: Margen directo objetivo % | N4: Costos directos reales ($) | O4: Utilidad directa real ($) | P4: Utilidad directa objetivo ($) | Q4: Cumplimiento utilidad directa % | R4: Asignación gastos fijos ($) | S4: Comisión Andrea ($) | T4: Utilidad operativa real ($) | U4: Margen operativo real % | V4: Semáforo
A5: Julio | B5: FAM-01 | C5: Notariales rápidos | D5: 4 | E5: 3 | F5: =IFERROR(E5/D5,0) -> 0.75 | G5: 35 | H5: =IFERROR(K5/E5,0) -> 20 | I5: =IFERROR(H5/G5-1,0) -> -0.42857143 | J5: 140 | K5: 60 | L5: =IFERROR(K5/J5,0) -> 0.42857143 | M5: 0.85 | N5: 0 | O5: =K5-N5 -> 60 | P5: 119 | Q5: =IFERROR(O5/P5,0) -> 0.50420168 | R5: =IFERROR(J5/SUM($J$5:$J$10)*SUM('07_Gastos_Fijos'!$D$5:$D$9),0) -> 102.5 | S5: 0 | T5: =O5-R5-S5 -> -42.5 | U5: =IFERROR(T5/K5,0) -> -0.70833333 | V5: =IF(L5>=1,"VERDE",IF(L5>=0.85,"AMARILLO","ROJO")) -> ROJO
A6: Julio | B6: FAM-02 | C6: Asesorías, contratos y gestiones | D6: 4 | E6: 4 | F6: =IFERROR(E6/D6,0) -> 1 | G6: 85 | H6: =IFERROR(K6/E6,0) -> 60 | I6: =IFERROR(H6/G6-1,0) -> -0.29411765 | J6: 340 | K6: 240 | L6: =IFERROR(K6/J6,0) -> 0.70588235 | M6: 0.9 | N6: 0 | O6: =K6-N6 -> 240 | P6: 306 | Q6: =IFERROR(O6/P6,0) -> 0.78431373 | R6: =IFERROR(J6/SUM($J$5:$J$10)*SUM('07_Gastos_Fijos'!$D$5:$D$9),0) -> 248.92857 | S6: 0 | T6: =O6-R6-S6 -> -8.9285714 | U6: =IFERROR(T6/K6,0) -> -0.037202381 | V6: =IF(L6>=1,"VERDE",IF(L6>=0.85,"AMARILLO","ROJO")) -> ROJO
A7: Julio | B7: FAM-03 | C7: Inmobiliario y registral | D7: 5 | E7: 1 | F7: =IFERROR(E7/D7,0) -> 0.2 | G7: 300 | H7: =IFERROR(K7/E7,0) -> 50 | I7: =IFERROR(H7/G7-1,0) -> -0.83333333 | J7: 1500 | K7: 50 | L7: =IFERROR(K7/J7,0) -> 0.033333333 | M7: 0.88 | N7: 0 | O7: =K7-N7 -> 50 | P7: 1320 | Q7: =IFERROR(O7/P7,0) -> 0.037878788 | R7: =IFERROR(J7/SUM($J$5:$J$10)*SUM('07_Gastos_Fijos'!$D$5:$D$9),0) -> 1098.2143 | S7: 0 | T7: =O7-R7-S7 -> -1048.2143 | U7: =IFERROR(T7/K7,0) -> -20.964286 | V7: =IF(L7>=1,"VERDE",IF(L7>=0.85,"AMARILLO","ROJO")) -> ROJO
A8: Julio | B8: FAM-04 | C8: Herencias y planificación patrimonial | D8: 1 | E8: 0 | F8: =IFERROR(E8/D8,0) -> 0 | G8: 750 | H8: =IFERROR(K8/E8,0) -> 0 | I8: =IFERROR(H8/G8-1,0) -> -1 | J8: 750 | K8: 0 | L8: =IFERROR(K8/J8,0) -> 0 | M8: 0.82 | N8: 0 | O8: =K8-N8 -> 0 | P8: 615 | Q8: =IFERROR(O8/P8,0) -> 0 | R8: =IFERROR(J8/SUM($J$5:$J$10)*SUM('07_Gastos_Fijos'!$D$5:$D$9),0) -> 549.10714 | S8: 0 | T8: =O8-R8-S8 -> -549.10714 | U8: =IFERROR(T8/K8,0) -> 0 | V8: =IF(L8>=1,"VERDE",IF(L8>=0.85,"AMARILLO","ROJO")) -> ROJO
A9: Julio | B9: FAM-05 | C9: Corporativo y administrativo especializado | D9: 1 | E9: 0 | F9: =IFERROR(E9/D9,0) -> 0 | G9: 350 | H9: =IFERROR(K9/E9,0) -> 0 | I9: =IFERROR(H9/G9-1,0) -> -1 | J9: 350 | K9: 0 | L9: =IFERROR(K9/J9,0) -> 0 | M9: 0.88 | N9: 0 | O9: =K9-N9 -> 0 | P9: 308 | Q9: =IFERROR(O9/P9,0) -> 0 | R9: =IFERROR(J9/SUM($J$5:$J$10)*SUM('07_Gastos_Fijos'!$D$5:$D$9),0) -> 256.25 | S9: 0 | T9: =O9-R9-S9 -> -256.25 | U9: =IFERROR(T9/K9,0) -> 0 | V9: =IF(L9>=1,"VERDE",IF(L9>=0.85,"AMARILLO","ROJO")) -> ROJO
A10: Julio | B10: FAM-06 | C10: Migración, relocalización y servicios internacionales | D10: 0 | E10: 0 | F10: =IFERROR(E10/D10,0) -> 0 | G10: 500 | H10: =IFERROR(K10/E10,0) -> 0 | I10: =IFERROR(H10/G10-1,0) -> -1 | J10: 0 | K10: 0 | L10: =IFERROR(K10/J10,0) -> 0 | M10: 0.82 | N10: 0 | O10: =K10-N10 -> 0 | P10: 0 | Q10: =IFERROR(O10/P10,0) -> 0 | R10: =IFERROR(J10/SUM($J$5:$J$10)*SUM('07_Gastos_Fijos'!$D$5:$D$9),0) -> 0 | S10: 0 | T10: =O10-R10-S10 -> 0 | U10: =IFERROR(T10/K10,0) -> 0 | V10: =IF(L10>=1,"VERDE",IF(L10>=0.85,"AMARILLO","ROJO")) -> ROJO
A11: Agosto | B11: FAM-01 | C11: Notariales rápidos | D11: 10 | E11: 0 | F11: =IFERROR(E11/D11,0) -> 0 | G11: 35 | H11: =IFERROR(K11/E11,0) -> 0 | I11: =IFERROR(H11/G11-1,0) -> -1 | J11: 350 | K11: 0 | L11: =IFERROR(K11/J11,0) -> 0 | M11: 0.85 | N11: 0 | O11: =K11-N11 -> 0 | P11: 297.5 | Q11: =IFERROR(O11/P11,0) -> 0 | R11: =IFERROR(J11/SUM($J$11:$J$16)*SUM('07_Gastos_Fijos'!$D$5:$D$9),0) -> 184.40421 | S11: 0 | T11: =O11-R11-S11 -> -184.40421 | U11: =IFERROR(T11/K11,0) -> 0 | V11: =IF(L11>=1,"VERDE",IF(L11>=0.85,"AMARILLO","ROJO")) -> ROJO
A12: Agosto | B12: FAM-02 | C12: Asesorías, contratos y gestiones | D12: 8 | E12: 0 | F12: =IFERROR(E12/D12,0) -> 0 | G12: 85 | H12: =IFERROR(K12/E12,0) -> 0 | I12: =IFERROR(H12/G12-1,0) -> -1 | J12: 680 | K12: 0 | L12: =IFERROR(K12/J12,0) -> 0 | M12: 0.9 | N12: 0 | O12: =K12-N12 -> 0 | P12: 612 | Q12: =IFERROR(O12/P12,0) -> 0 | R12: =IFERROR(J12/SUM($J$11:$J$16)*SUM('07_Gastos_Fijos'!$D$5:$D$9),0) -> 358.27103 | S12: 0 | T12: =O12-R12-S12 -> -358.27103 | U12: =IFERROR(T12/K12,0) -> 0 | V12: =IF(L12>=1,"VERDE",IF(L12>=0.85,"AMARILLO","ROJO")) -> ROJO
A13: Agosto | B13: FAM-03 | C13: Inmobiliario y registral | D13: 3 | E13: 0 | F13: =IFERROR(E13/D13,0) -> 0 | G13: 300 | H13: =IFERROR(K13/E13,0) -> 0 | I13: =IFERROR(H13/G13-1,0) -> -1 | J13: 900 | K13: 0 | L13: =IFERROR(K13/J13,0) -> 0 | M13: 0.88 | N13: 0 | O13: =K13-N13 -> 0 | P13: 792 | Q13: =IFERROR(O13/P13,0) -> 0 | R13: =IFERROR(J13/SUM($J$11:$J$16)*SUM('07_Gastos_Fijos'!$D$5:$D$9),0) -> 474.18224 | S13: 0 | T13: =O13-R13-S13 -> -474.18224 | U13: =IFERROR(T13/K13,0) -> 0 | V13: =IF(L13>=1,"VERDE",IF(L13>=0.85,"AMARILLO","ROJO")) -> ROJO
A14: Agosto | B14: FAM-04 | C14: Herencias y planificación patrimonial | D14: 2 | E14: 0 | F14: =IFERROR(E14/D14,0) -> 0 | G14: 750 | H14: =IFERROR(K14/E14,0) -> 0 | I14: =IFERROR(H14/G14-1,0) -> -1 | J14: 1500 | K14: 0 | L14: =IFERROR(K14/J14,0) -> 0 | M14: 0.82 | N14: 0 | O14: =K14-N14 -> 0 | P14: 1230 | Q14: =IFERROR(O14/P14,0) -> 0 | R14: =IFERROR(J14/SUM($J$11:$J$16)*SUM('07_Gastos_Fijos'!$D$5:$D$9),0) -> 790.30374 | S14: 0 | T14: =O14-R14-S14 -> -790.30374 | U14: =IFERROR(T14/K14,0) -> 0 | V14: =IF(L14>=1,"VERDE",IF(L14>=0.85,"AMARILLO","ROJO")) -> ROJO
A15: Agosto | B15: FAM-05 | C15: Corporativo y administrativo especializado | D15: 1 | E15: 0 | F15: =IFERROR(E15/D15,0) -> 0 | G15: 350 | H15: =IFERROR(K15/E15,0) -> 0 | I15: =IFERROR(H15/G15-1,0) -> -1 | J15: 350 | K15: 0 | L15: =IFERROR(K15/J15,0) -> 0 | M15: 0.88 | N15: 0 | O15: =K15-N15 -> 0 | P15: 308 | Q15: =IFERROR(O15/P15,0) -> 0 | R15: =IFERROR(J15/SUM($J$11:$J$16)*SUM('07_Gastos_Fijos'!$D$5:$D$9),0) -> 184.40421 | S15: 0 | T15: =O15-R15-S15 -> -184.40421 | U15: =IFERROR(T15/K15,0) -> 0 | V15: =IF(L15>=1,"VERDE",IF(L15>=0.85,"AMARILLO","ROJO")) -> ROJO
A16: Agosto | B16: FAM-06 | C16: Migración, relocalización y servicios internacionales | D16: 1 | E16: 0 | F16: =IFERROR(E16/D16,0) -> 0 | G16: 500 | H16: =IFERROR(K16/E16,0) -> 0 | I16: =IFERROR(H16/G16-1,0) -> -1 | J16: 500 | K16: 0 | L16: =IFERROR(K16/J16,0) -> 0 | M16: 0.82 | N16: 0 | O16: =K16-N16 -> 0 | P16: 410 | Q16: =IFERROR(O16/P16,0) -> 0 | R16: =IFERROR(J16/SUM($J$11:$J$16)*SUM('07_Gastos_Fijos'!$D$5:$D$9),0) -> 263.43458 | S16: 0 | T16: =O16-R16-S16 -> -263.43458 | U16: =IFERROR(T16/K16,0) -> 0 | V16: =IF(L16>=1,"VERDE",IF(L16>=0.85,"AMARILLO","ROJO")) -> ROJO
A17: Septiembre | B17: FAM-01 | C17: Notariales rápidos | D17: 11 | E17: 0 | F17: =IFERROR(E17/D17,0) -> 0 | G17: 35 | H17: =IFERROR(K17/E17,0) -> 0 | I17: =IFERROR(H17/G17-1,0) -> -1 | J17: 385 | K17: 0 | L17: =IFERROR(K17/J17,0) -> 0 | M17: 0.85 | N17: 0 | O17: =K17-N17 -> 0 | P17: 327.25 | Q17: =IFERROR(O17/P17,0) -> 0 | R17: =IFERROR(J17/SUM($J$17:$J$22)*SUM('07_Gastos_Fijos'!$D$5:$D$9),0) -> 237.85616 | S17: 0 | T17: =O17-R17-S17 -> -237.85616 | U17: =IFERROR(T17/K17,0) -> 0 | V17: =IF(L17>=1,"VERDE",IF(L17>=0.85,"AMARILLO","ROJO")) -> ROJO
A18: Septiembre | B18: FAM-02 | C18: Asesorías, contratos y gestiones | D18: 9 | E18: 0 | F18: =IFERROR(E18/D18,0) -> 0 | G18: 85 | H18: =IFERROR(K18/E18,0) -> 0 | I18: =IFERROR(H18/G18-1,0) -> -1 | J18: 765 | K18: 0 | L18: =IFERROR(K18/J18,0) -> 0 | M18: 0.9 | N18: 0 | O18: =K18-N18 -> 0 | P18: 688.5 | Q18: =IFERROR(O18/P18,0) -> 0 | R18: =IFERROR(J18/SUM($J$17:$J$22)*SUM('07_Gastos_Fijos'!$D$5:$D$9),0) -> 472.62329 | S18: 0 | T18: =O18-R18-S18 -> -472.62329 | U18: =IFERROR(T18/K18,0) -> 0 | V18: =IF(L18>=1,"VERDE",IF(L18>=0.85,"AMARILLO","ROJO")) -> ROJO
A19: Septiembre | B19: FAM-03 | C19: Inmobiliario y registral | D19: 3 | E19: 0 | F19: =IFERROR(E19/D19,0) -> 0 | G19: 300 | H19: =IFERROR(K19/E19,0) -> 0 | I19: =IFERROR(H19/G19-1,0) -> -1 | J19: 900 | K19: 0 | L19: =IFERROR(K19/J19,0) -> 0 | M19: 0.88 | N19: 0 | O19: =K19-N19 -> 0 | P19: 792 | Q19: =IFERROR(O19/P19,0) -> 0 | R19: =IFERROR(J19/SUM($J$17:$J$22)*SUM('07_Gastos_Fijos'!$D$5:$D$9),0) -> 556.0274 | S19: 0 | T19: =O19-R19-S19 -> -556.0274 | U19: =IFERROR(T19/K19,0) -> 0 | V19: =IF(L19>=1,"VERDE",IF(L19>=0.85,"AMARILLO","ROJO")) -> ROJO
A20: Septiembre | B20: FAM-04 | C20: Herencias y planificación patrimonial | D20: 1 | E20: 0 | F20: =IFERROR(E20/D20,0) -> 0 | G20: 750 | H20: =IFERROR(K20/E20,0) -> 0 | I20: =IFERROR(H20/G20-1,0) -> -1 | J20: 750 | K20: 0 | L20: =IFERROR(K20/J20,0) -> 0 | M20: 0.82 | N20: 0 | O20: =K20-N20 -> 0 | P20: 615 | Q20: =IFERROR(O20/P20,0) -> 0 | R20: =IFERROR(J20/SUM($J$17:$J$22)*SUM('07_Gastos_Fijos'!$D$5:$D$9),0) -> 463.35616 | S20: 0 | T20: =O20-R20-S20 -> -463.35616 | U20: =IFERROR(T20/K20,0) -> 0 | V20: =IF(L20>=1,"VERDE",IF(L20>=0.85,"AMARILLO","ROJO")) -> ROJO
